<?xml version="1.0"?>
<robot name="robodog">

<material name="Blue">
    <color rgba="0.0 0.0 0.8 1.0"/>
</material>

<material name="Dark_Blue">
    <color rgba="0.0 0.0 0.7 1.0"/>
</material>


<link name="base_link">

    <collision>
        <origin rpy="0.0 0.0 0.0" xyz="0.0 0.0 0.0"/>
        <geometry>
        <box size="0.4 0.25 0.05"/>
        </geometry>
    </collision>

    <visual>
        <origin rpy="0.0 0.0 0.0" xyz="0.0 0.0 0.0"/>
        <geometry>
        <box size="0.4 0.25 0.05"/>
        </geometry>
        <material name="Blue"/>
    </visual>

    <inertial>
        <mass value="30.0"/>
        <inertia
            ixx="1.0" ixy="0.0" ixz="0.0"
            iyy="1.0" iyz="0.0"
            izz="1.0"/>
    </inertial>

</link>


<link name="lidar_link">

    <collision>
        <origin rpy="0.0 0.0 0.0" xyz="0.0 0.0 0.0"/>
        <geometry>
        <cylinder radius="0.03" length="0.03"/>
        </geometry>
    </collision>

    <visual>
        <origin rpy="0.0 0.0 0.0" xyz="0.0 0.0 0.0"/>
        <geometry>
         <cylinder radius="0.03" length="0.03"/>
        </geometry>
        <material name="Blue"/>
    </visual>

    <inertial>
        <mass value="0.1"/>
        <inertia
            ixx="1.0" ixy="0.0" ixz="0.0"
            iyy="1.0" iyz="0.0"
            izz="1.0"/>
    </inertial>

</link>

<joint name="lidar_base" type="fixed">
    <origin xyz="0.14 0.0 0.055" rpy="0.0 0.0 3.14"/>
    <parent link="base_link"/>
    <child link="lidar_link"/>
</joint>


<link name="kinect_link">

    <collision>
        <origin rpy="0.0 0.0 0.0" xyz="0.0 0.0 0.0"/>
        <geometry>
            <box size="0.00 0.00 0.00"/>
        </geometry>
    </collision>

    <visual>
        <origin rpy="0.0 0.0 0.0" xyz="0.0 0.0 0.0"/>
        <geometry>
            <box size="0.02 0.08 0.02"/>
        </geometry>
        <material name="Blue"/>
    </visual>

    <inertial>
        <mass value="0.1"/>
        <inertia
            ixx="1.0" ixy="0.0" ixz="0.0"
            iyy="1.0" iyz="0.0"
            izz="1.0"/>
    </inertial>

</link>

<joint name="kinect_base" type="fixed">
    <origin xyz="0.20 0.0 0.01" rpy="0.0 0.0 0.0"/>
    <parent link="base_link"/>
    <child link="kinect_link"/>
</joint>

<joint name="kinect_camera" type="fixed">
    <origin xyz="0.00 0.0 0.000" rpy="-1.57 0.0 -1.57"/>
    <parent link="kinect_link"/>
    <child link="camera_link"/>
</joint>

<link name="camera_link"> </link>


<link name="imu_link">

    <collision>
        <origin rpy="0.0 0.0 0.0" xyz="0.0 0.0 0.0"/>
        <geometry>
        <cylinder radius="0.2" length="0.01"/>
        </geometry>
    </collision>

    <visual>
        <origin rpy="0.0 0.0 0.0" xyz="0.0 0.0 0.0"/>
        <geometry>
         <cylinder radius="0.01" length="0.01"/>
        </geometry>
        <material name="Blue"/>
    </visual>

    <inertial>
        <mass value="0.02"/>
        <inertia
            ixx="1.0" ixy="0.0" ixz="0.0"
            iyy="1.0" iyz="0.0"
            izz="1.0"/>
    </inertial>

</link>

<joint name="imu_base" type="fixed">
    <origin xyz="0.0 0.0 0.0" rpy="0.0 0.0 0.0"/>
    <parent link="base_link"/>
    <child link="imu_link"/>
</joint>

<!-- Front Left Leg-->
<joint name="base_leg_fl" type="revolute">
    <origin xyz="0.13 0.13 -0.005" rpy="0.0 1.57 0.0"/>
    <parent link="base_link"/>
    <child link="robo_leg_fl_hip"/>
    <axis xyz="0.0 0.0 1.0"/>
    <limit lower="-3.14" upper="3.14" effort="15.0" velocity="20.5"/>
</joint>

<link name="robo_leg_fl_hip">

    <visual>
    <origin rpy="0.0 0.0 0.0" xyz="0.0 0.0 -0.01"/>
        <geometry>
        <box size="0.03 0.02 0.03"/>
        </geometry>
        <material name="Blue"/>
    </visual>

    <collision>
        <origin rpy="0.0 0.0 0.0" xyz="0.0 0.0 -0.01"/>
        <geometry>
        <box size="0.03 0.02 0.03"/>
        </geometry>
    </collision>

    <inertial>
        <mass value="0.3"/>
        <inertia
            ixx="0.0" ixy="0.0" ixz="0.0"
            iyy="0.0" iyz="0.0"
            izz="0.0"/>
    </inertial>

</link>

<joint name="hip_leg_fl" type="revolute">
    <origin xyz="0.0 0.015 0.0" rpy="0.0 -0.0 -1.57"/>
    <parent link="robo_leg_fl_hip"/>
    <child link="robo_leg_fl_up"/>
    <axis xyz="0.0 -1.0 0.0"/>
    <limit lower="-3.14" upper="3.14" effort="17.0" velocity="20.5"/>
</joint>

<link name="robo_leg_fl_up">

    <visual>
    <origin rpy="0.0 0.0 0.0" xyz="0.0 0.0 -0.06"/>
        <geometry>
        <box size="0.03 0.033 0.12"/>
        </geometry>
        <material name="Blue"/>
    </visual>

    <inertial>
        <mass value="0.3"/>
        <inertia
            ixx="1.0" ixy="0.0" ixz="0.0"
            iyy="1.0" iyz="0.0"
            izz="1.0"/>
    </inertial>

    <collision>
       <origin rpy="0.0 0.0 0.0" xyz="0.0 0.0 -0.06"/>
        <geometry>
        <box size="0.03 0.033 0.12"/>
        </geometry>
    </collision>

</link>

<joint name="leg_fl_up_down" type="revolute">
    <origin xyz="0.0 -0.015 -0.12" rpy="0.0 3.14 0.0"/>
    <parent link="robo_leg_fl_up"/>
    <child link="robo_leg_fl_down"/>
    <axis xyz="0.0 1.0 0.0"/>
    <limit lower="-3.14" upper="3.14" effort="17.0" velocity="20.5"/>
</joint>

<link name="robo_leg_fl_down">
    <visual>
    <origin rpy="0.0 0.0 0.0" xyz="0.0 0.0 -0.075"/>
        <geometry>
        <box size="0.0145 0.01 0.15"/>
        </geometry>
        <material name="Blue"/>
    </visual>

    <collision>
       <origin rpy="0.0 0.0 0.0" xyz="0.0 0.0 -0.075"/>
        <geometry>
        <box size="0.0145 0.01 0.15"/>
        </geometry>
    </collision>

    <inertial>
        <mass value="0.3"/>
        <inertia
            ixx="1.0" ixy="0.0" ixz="0.0"
            iyy="1.0" iyz="0.0"
            izz="1.0"/>
    </inertial>

</link>

<joint name="leg_fl_down_sphere_joint" type="fixed">
    <origin xyz="0.0 0.00 -0.075" rpy="0.0 0.0 0.0"/>
    <parent link="robo_leg_fl_down"/>
    <child link="leg_fl_down_sphere"/>
</joint>

<link name="leg_fl_down_sphere">
    <visual>
    <origin rpy="0.0 0.0 0.0" xyz="0.0 0.0 -0.075"/>
        <geometry>
        <sphere radius="0.012"/>
        </geometry>
        <material name="Blue"/>
    </visual>

    <collision>
       <origin rpy="0.0 0.0 0.0" xyz="0.0 0.0 -0.075"/>
        <geometry>
         <sphere radius="0.01"/>
        </geometry>
    </collision>

    <inertial>
        <mass value="0.01"/>
        <inertia
            ixx="1.0" ixy="0.0" ixz="0.0"
            iyy="1.0" iyz="0.0"
            izz="1.0"/>
    </inertial>

</link>

<!-- Front Right Leg-->
<joint name="base_leg_fr" type="revolute">
    <origin xyz="0.13 -0.13 -0.005" rpy="0.0 1.57 0.0"/>
    <parent link="base_link"/>
    <child link="robo_leg_fr_hip"/>
    <axis xyz="0.0 0.0 -1.0"/>
    <limit lower="-3.14" upper="3.14" effort="15.0" velocity="20.5"/>
</joint>

<link name="robo_leg_fr_hip">
    <visual>
    <origin rpy="0.0 0.0 0.0" xyz="0.0 0.0 -0.01"/>
        <geometry>
        <box size="0.03 0.02 0.03"/>
        </geometry>
        <material name="Blue"/>
    </visual>

    <collision>
            <origin rpy="0.0 0.0 0.0" xyz="0.0 0.0 -0.01"/>
        <geometry>
        <box size="0.03 0.02 0.03"/>
        </geometry>
    </collision>

    <inertial>
            <mass value="0.3"/>
            <inertia
                ixx="1.0" ixy="0.0" ixz="0.0"
                iyy="1.0" iyz="0.0"
                izz="1.0"/>
    </inertial>
</link>

<joint name="hip_leg_fr" type="revolute">
    <origin xyz="0.0 -0.015 0.0" rpy="0.0 -0.0 1.57"/>
    <parent link="robo_leg_fr_hip"/>
    <child link="robo_leg_fr_up"/>
    <axis xyz="0.0 -1.0 0.0"/>
    <limit lower="-3.14" upper="3.14" effort="17.0" velocity="20.5"/>
</joint>

<link name="robo_leg_fr_up">
    <visual>
    <origin rpy="0.0 0.0 0.0" xyz="0.0 0.0 -0.06"/>
        <geometry>
        <box size="0.03 0.033 0.12"/>
        </geometry>
        <material name="Blue"/>
    </visual>

    <collision>
           <origin rpy="0.0 0.0 0.0" xyz="0.0 0.0 -0.06"/>
    <geometry>
    <box size="0.03 0.033 0.12"/>
    </geometry>
    </collision>

    <inertial>
            <mass value="0.3"/>
            <inertia
                ixx="1.0" ixy="0.0" ixz="0.0"
                iyy="1.0" iyz="0.0"
                izz="1.0"/>
    </inertial>

</link>

<joint name="leg_fr_up_down" type="revolute">
    <origin xyz="0.0 0.015 -0.12" rpy="0.0 3.14 0.0"/>
    <parent link="robo_leg_fr_up"/>
    <child link="robo_leg_fr_down"/>
    <axis xyz="0.0 1.0 0.0"/>
    <limit lower="-3.14" upper="3.14" effort="17.0" velocity="20.5"/>
</joint>

<link name="robo_leg_fr_down">
    <visual>
    <origin rpy="0.0 0.0 0.0" xyz="0.0 0.0 -0.075"/>
        <geometry>
        <box size="0.0145 0.01 0.15"/>
        </geometry>
        <material name="Blue"/>
    </visual>

    <collision>
          <origin rpy="0.0 0.0 0.0" xyz="0.0 0.0 -0.075"/>
        <geometry>
        <box size="0.0145 0.01 0.15"/>
        </geometry>
    </collision>

    <inertial>
            <mass value="0.3"/>
            <inertia
                ixx="1.0" ixy="0.0" ixz="0.0"
                iyy="1.0" iyz="0.0"
                izz="1.0"/>
    </inertial>

</link>

<joint name="leg_fr_down_sphere_joint" type="fixed">
    <origin xyz="0.0 0.00 -0.075" rpy="0.0 0.0 0.0"/>
    <parent link="robo_leg_fr_down"/>
    <child link="leg_fr_down_sphere"/>
</joint>

<link name="leg_fr_down_sphere">
    <visual>
    <origin rpy="0.0 0.0 0.0" xyz="0.0 0.0 -0.075"/>
        <geometry>
        <sphere radius="0.012"/>
        </geometry>
        <material name="Blue"/>
    </visual>

    <collision>
       <origin rpy="0.0 0.0 0.0" xyz="0.0 0.0 -0.075"/>
        <geometry>
         <sphere radius="0.01"/>
        </geometry>
    </collision>

    <inertial>
        <mass value="0.01"/>
        <inertia
            ixx="1.0" ixy="0.0" ixz="0.0"
            iyy="1.0" iyz="0.0"
            izz="1.0"/>
    </inertial>

</link>

<!-- Back Left Leg-->
<joint name="base_leg_bl" type="revolute">
    <origin xyz="-0.13 0.13 -0.005" rpy="0.0 1.57 0.0"/>
    <parent link="base_link"/>
    <child link="robo_leg_bl_hip"/>
    <axis xyz="0.0 0.0 1.0"/>
    <limit lower="-3.14" upper="3.14" effort="25.0" velocity="20.7"/>
</joint>

<link name="robo_leg_bl_hip">
    <visual>
    <origin rpy="0.0 0.0 0.0" xyz="0.0 0.0 -0.01"/>
        <geometry>
        <box size="0.03 0.02 0.03"/>
        </geometry>
        <material name="Blue"/>
    </visual>

    <collision>
          <origin rpy="0.0 0.0 0.0" xyz="0.0 0.0 -0.01"/>
        <geometry>
        <box size="0.03 0.02 0.03"/>
        </geometry>
    </collision>

    <inertial>
            <mass value="0.3"/>
            <inertia
                ixx="1.0" ixy="0.0" ixz="0.0"
                iyy="1.0" iyz="0.0"
                izz="1.0"/>
    </inertial>

</link>

<joint name="hip_leg_bl" type="revolute">
    <origin xyz="0.0 0.015 0.0" rpy="0.0 -0.0 -1.57"/>
    <parent link="robo_leg_bl_hip"/>
    <child link="robo_leg_bl_up"/>
    <axis xyz="0.0 -1.0 0.0"/>
    <limit lower="-3.14" upper="3.14" effort="27.0" velocity="20.7"/>
</joint>

<link name="robo_leg_bl_up">
    <visual>
    <origin rpy="0.0 0.0 0.0" xyz="0.0 0.0 -0.06"/>
        <geometry>
        <box size="0.03 0.033 0.12"/>
        </geometry>
        <material name="Blue"/>
    </visual>

    <collision>
          <origin rpy="0.0 0.0 0.0" xyz="0.0 0.0 -0.06"/>
        <geometry>
        <box size="0.03 0.033 0.12"/>
        </geometry>
    </collision>

    <inertial>
            <mass value="0.3"/>
            <inertia
                ixx="1.0" ixy="0.0" ixz="0.0"
                iyy="1.0" iyz="0.0"
                izz="1.0"/>
    </inertial>

</link>

<joint name="leg_bl_up_down" type="revolute">
    <origin xyz="0.0 -0.015 -0.12" rpy="0.0 3.14 0.0"/>
    <parent link="robo_leg_bl_up"/>
    <child link="robo_leg_bl_down"/>
    <axis xyz="0.0 1.0 0.0"/>
    <limit lower="-3.14" upper="3.14" effort="27.0" velocity="20.7"/>
</joint>

<link name="robo_leg_bl_down">
    <visual>
    <origin rpy="0.0 0.0 0.0" xyz="0.0 0.0 -0.075"/>
        <geometry>
        <box size="0.0145 0.01 0.15"/>
        </geometry>
        <material name="Blue"/>
    </visual>
    <collision>
          <origin rpy="0.0 0.0 0.0" xyz="0.0 0.0 -0.075"/>
        <geometry>
        <box size="0.0145 0.01 0.15"/>
        </geometry>
    </collision>

    <inertial>
          <origin rpy="0.0 0.0 0.0" xyz="0.0 0.0 -0.075"/>
            <mass value="0.3"/>
            <inertia
                ixx="1.0" ixy="0.0" ixz="0.0"
                iyy="1.0" iyz="0.0"
                izz="1.0"/>
    </inertial>
</link>

<joint name="leg_bl_down_sphere_joint" type="fixed">
    <origin xyz="0.0 0.00 -0.075" rpy="0.0 0.0 0.0"/>
    <parent link="robo_leg_bl_down"/>
    <child link="leg_bl_down_sphere"/>
</joint>

<link name="leg_bl_down_sphere">
    <visual>
    <origin rpy="0.0 0.0 0.0" xyz="0.0 0.0 -0.075"/>
        <geometry>
        <sphere radius="0.012"/>
        </geometry>
        <material name="Blue"/>
    </visual>

    <collision>
       <origin rpy="0.0 0.0 0.0" xyz="0.0 0.0 -0.075"/>
        <geometry>
         <sphere radius="0.01"/>
        </geometry>
    </collision>

    <inertial>
        <mass value="0.01"/>
        <inertia
            ixx="1.0" ixy="0.0" ixz="0.0"
            iyy="1.0" iyz="0.0"
            izz="1.0"/>
    </inertial>

</link>

<!-- Back Right Leg-->
<joint name="base_leg_br" type="revolute">
    <origin xyz="-0.13 -0.13 -0.005" rpy="0.0 1.57 0.0"/>
    <parent link="base_link"/>
    <child link="robo_leg_br_hip"/>
    <axis xyz="0.0 0.0 -1.0"/>
    <limit lower="-3.14" upper="3.14" effort="25.0" velocity="20.7"/>
</joint>

<link name="robo_leg_br_hip">
    <visual>
    <origin rpy="0.0 0.0 0.0" xyz="0.0 0.0 -0.01"/>
        <geometry>
        <box size="0.03 0.02 0.03"/>
        </geometry>
        <material name="Blue"/>
    </visual>
    <collision>
         <origin rpy="0.0 0.0 0.0" xyz="0.0 0.0 -0.01"/>
        <geometry>
        <box size="0.03 0.02 0.03"/>
        </geometry>
    </collision>

    <inertial>
            <mass value="0.3"/>
            <inertia
                ixx="1.0" ixy="0.0" ixz="0.0"
                iyy="1.0" iyz="0.0"
                izz="1.0"/>
    </inertial>
</link>

<joint name="hip_leg_br" type="revolute">
    <origin xyz="0.0 -0.02 0.0" rpy="0.0 -0.0 1.57"/>
    <parent link="robo_leg_br_hip"/>
    <child link="robo_leg_br_up"/>
    <axis xyz="0.0 -1.0 0.0"/>
    <limit lower="-3.14" upper="3.14" effort="25.0" velocity="20.7"/>
</joint>

<link name="robo_leg_br_up">
    <visual>
    <origin rpy="0.0 0.0 0.0" xyz="0.0 0.0 -0.06"/>
        <geometry>
        <box size="0.03 0.033 0.12"/>
        </geometry>
        <material name="Blue"/>
    </visual>

    <collision>
         <origin rpy="0.0 0.0 0.0" xyz="0.0 0.0 -0.06"/>
        <geometry>
        <box size="0.03 0.033 0.12"/>
        </geometry>
    </collision>

    <inertial>
            <mass value="0.3"/>
            <inertia
                ixx="1.0" ixy="0.0" ixz="0.0"
                iyy="1.0" iyz="0.0"
                izz="1.0"/>
    </inertial>
</link>

<joint name="leg_br_up_down" type="revolute">
    <origin xyz="0.0 0.0 -0.12" rpy="0.0 3.14 0.0"/>
    <parent link="robo_leg_br_up"/>
    <child link="robo_leg_br_down"/>
    <axis xyz="0.0 1.0 0.0"/>
    <limit lower="-3.14" upper="3.14" effort="25.0" velocity="20.7"/>
</joint>

<link name="robo_leg_br_down">
    <visual>
    <origin rpy="0.0 0.0 0.0" xyz="0.0 0.0 -0.075"/>
        <geometry>
        <box size="0.0145 0.01 0.15"/>
        </geometry>
        <material name="Blue"/>
    </visual>

    <collision>
        <origin rpy="0.0 0.0 0.0" xyz="0.0 0.0 -0.075"/>
        <geometry>
        <box size="0.0145 0.01 0.15"/>
        </geometry>
    </collision>

    <inertial>
            <mass value="0.3"/>
            <inertia
                ixx="1.0" ixy="0.0" ixz="0.0"
                iyy="1.0" iyz="0.0"
                izz="1.0"/>
    </inertial>

</link>

<joint name="leg_br_down_sphere_joint" type="fixed">
    <origin xyz="0.0 0.00 -0.075" rpy="0.0 0.0 0.0"/>
    <parent link="robo_leg_br_down"/>
    <child link="leg_br_down_sphere"/>
</joint>

<link name="leg_br_down_sphere">
    <visual>
    <origin rpy="0.0 0.0 0.0" xyz="0.0 0.0 -0.075"/>
        <geometry>
        <sphere radius="0.012"/>
        </geometry>
        <material name="Blue"/>
    </visual>

    <collision>
       <origin rpy="0.0 0.0 0.0" xyz="0.0 0.0 -0.075"/>
        <geometry>
         <sphere radius="0.01"/>
        </geometry>
    </collision>

    <inertial>
        <mass value="0.01"/>
        <inertia
            ixx="1.0" ixy="0.0" ixz="0.0"
            iyy="1.0" iyz="0.0"
            izz="1.0"/>
    </inertial>

</link>

 <gazebo>
    <plugin name="gazebo_ros_control" filename="libgazebo_ros_control.so">
      <robotNamespace>/</robotNamespace>
    </plugin>
</gazebo>

<transmission name="fl_shoulder_trans">
    <type>transmission_interface/SimpleTransmission</type>
    <actuator name="fl_shoulder_motor">
      <mechanicalReduction>5</mechanicalReduction>
    </actuator>
    <joint name="base_leg_fl">
      <hardwareInterface>hardware_interface/EffortJointInterface</hardwareInterface>
    </joint>
</transmission>


<transmission name="fl_hip_trans">
    <type>transmission_interface/SimpleTransmission</type>
    <actuator name="fl_hip_motor">
      <mechanicalReduction>5</mechanicalReduction>
    </actuator>
    <joint name="hip_leg_fl">
      <hardwareInterface>hardware_interface/EffortJointInterface</hardwareInterface>
    </joint>
</transmission>


<transmission name="fl_knee_trans">
    <type>transmission_interface/SimpleTransmission</type>
    <actuator name="fl_knee_motor">
      <mechanicalReduction>5</mechanicalReduction>
    </actuator>
    <joint name="leg_fl_up_down">
      <hardwareInterface>hardware_interface/EffortJointInterface</hardwareInterface>
    </joint>
</transmission>


<transmission name="fr_shoulder_trans">
    <type>transmission_interface/SimpleTransmission</type>
    <actuator name="fr_shoulder_motor">
      <mechanicalReduction>5</mechanicalReduction>
    </actuator>
    <joint name="base_leg_fr">
      <hardwareInterface>hardware_interface/EffortJointInterface</hardwareInterface>
    </joint>
</transmission>


<transmission name="fr_hip_trans">
    <type>transmission_interface/SimpleTransmission</type>
    <actuator name="fr_hip_motor">
      <mechanicalReduction>5</mechanicalReduction>
    </actuator>
    <joint name="hip_leg_fr">
      <hardwareInterface>hardware_interface/EffortJointInterface</hardwareInterface>
    </joint>
</transmission>


<transmission name="fr_knee_trans">
    <type>transmission_interface/SimpleTransmission</type>
    <actuator name="fr_knee_motor">
      <mechanicalReduction>5</mechanicalReduction>
    </actuator>
    <joint name="leg_fr_up_down">
      <hardwareInterface>hardware_interface/EffortJointInterface</hardwareInterface>
    </joint>
</transmission>

<transmission name="bl_shoulder_trans">
    <type>transmission_interface/SimpleTransmission</type>
    <actuator name="bl_shoulder_motor">
      <mechanicalReduction>5</mechanicalReduction>
    </actuator>
    <joint name="base_leg_bl">
      <hardwareInterface>hardware_interface/EffortJointInterface</hardwareInterface>
    </joint>
</transmission>


<transmission name="bl_hip_trans">
    <type>transmission_interface/SimpleTransmission</type>
    <actuator name="bl_hip_motor">
      <mechanicalReduction>5</mechanicalReduction>
    </actuator>
    <joint name="hip_leg_bl">
      <hardwareInterface>hardware_interface/EffortJointInterface</hardwareInterface>
    </joint>
</transmission>


<transmission name="bl_knee_trans">
    <type>transmission_interface/SimpleTransmission</type>
    <actuator name="bl_knee_motor">
      <mechanicalReduction>5</mechanicalReduction>
    </actuator>
    <joint name="leg_bl_up_down">
      <hardwareInterface>hardware_interface/EffortJointInterface</hardwareInterface>
    </joint>
</transmission>

<transmission name="br_shoulder_trans">
    <type>transmission_interface/SimpleTransmission</type>
    <actuator name="br_shoulder_motor">
      <mechanicalReduction>5</mechanicalReduction>
    </actuator>
    <joint name="base_leg_br">
      <hardwareInterface>hardware_interface/EffortJointInterface</hardwareInterface>
    </joint>
</transmission>


<transmission name="br_hip_trans">
    <type>transmission_interface/SimpleTransmission</type>
    <actuator name="br_hip_motor">
      <mechanicalReduction>5</mechanicalReduction>
    </actuator>
    <joint name="hip_leg_br">
      <hardwareInterface>hardware_interface/EffortJointInterface</hardwareInterface>
    </joint>
</transmission>


<transmission name="br_knee_trans">
    <type>transmission_interface/SimpleTransmission</type>
    <actuator name="br_knee_motor">
      <mechanicalReduction>5</mechanicalReduction>
    </actuator>
    <joint name="leg_br_up_down">
      <hardwareInterface>hardware_interface/EffortJointInterface</hardwareInterface>
    </joint>
</transmission>

<gazebo reference="leg_fl_down_sphere">
    <mu1>1.0</mu1>
    <mu2>1.0</mu2>
    <minDepth>0.0002</minDepth>
    <kp  value="10000000.0"/>
    <kd  value="100.0"/>
  </gazebo>

  <!-- FL4 friction -->
  <gazebo reference="leg_fr_down_sphere">
    <mu1>1.0</mu1>
    <mu2>1.0</mu2>
    <minDepth>0.0002</minDepth>
    <kp  value="10000000.0"/>
    <kd  value="100.0"/>
  </gazebo>

  <!-- RR4 friction -->
  <gazebo reference="leg_bl_down_sphere">
    <mu1>1.0</mu1>
    <mu2>1.0</mu2>
    <minDepth>0.0002</minDepth>
    <kp  value="10000000.0"/>
    <kd  value="100.0"/>
  </gazebo>

  <!-- RL4 friction -->
  <gazebo reference="leg_br_down_sphere">
    <mu1>1.0</mu1>
    <mu2>1.0</mu2>
    <minDepth>0.0002</minDepth>
    <kp  value="100000000.0"/>
    <kd  value="100.0"/>
  </gazebo>


 <gazebo reference="lidar_link">
    <sensor type="ray" name="head_hokuyo_sensor">
      <pose>0 0 0 0 0 0</pose>
      <visualize>false</visualize>
      <update_rate>20</update_rate>
      <ray>
        <scan>
          <horizontal>
            <samples>720</samples>
            <resolution>1</resolution>
            <min_angle>-0.72796</min_angle>
            <max_angle>0.72796</max_angle>
          </horizontal>
        </scan>
        <range>
          <min>0.10</min>
          <max>30.0</max>
          <resolution>0.01</resolution>
        </range>
        <noise>
          <type>gaussian</type>
          <mean>0.0</mean>
          <stddev>0.0</stddev>
        </noise>
      </ray>
      <plugin name="gazebo_ros_head_hokuyo_controller" filename="libgazebo_ros_laser.so">
        <topicName>/scan</topicName>
        <frameName>lidar_link</frameName>
      </plugin>
    </sensor>
  </gazebo>

  <gazebo reference="kinect_link">
  <sensor name="kinect_camera" type="depth">
    <update_rate>20</update_rate>
    <camera>
      <horizontal_fov>1.0898</horizontal_fov>
      <image>
        <width>640</width>
        <height>480</height>
        <format>R8G8B8</format>
      </image>
      <clip>
        <near>0.05</near>
        <far>10.0</far>
      </clip>
    </camera>
    <plugin name="kinect_controller" filename="libgazebo_ros_openni_kinect.so">
      <cameraName>kinect</cameraName>
      <imageTopicName>/kinect/color/image_raw</imageTopicName>
      <cameraInfoTopicName>/kinect/color/camera_info</cameraInfoTopicName>
      <depthImageTopicName>/kinect/depth/image_raw</depthImageTopicName>
      <depthImageInfoTopicName>/kinect/depth/camera_info</depthImageInfoTopicName>
      <pointCloudTopicName>/kinect/depth/points</pointCloudTopicName>
      <frameName>camera_link</frameName>
    </plugin>
  </sensor>
</gazebo>

   <gazebo>
    <plugin name="imu_plugin" filename="libgazebo_ros_imu.so">
      <alwaysOn>true</alwaysOn>
      <bodyName>imu_link</bodyName>
      <topicName>imu</topicName>
      <serviceName>imu_service</serviceName>
      <gaussianNoise>0.0</gaussianNoise>
      <updateRate>20.0</updateRate>
    </plugin>
  </gazebo>

</robot>